Workbook

Sheet StandardParams
A1: 属性分类 | B1: 属性名 | C1: 基础数值 | D1: 成长/级 | E1: 资质 | F1: 经脉
A2: 基础属性 | B2: 臂力 | C2: 10 | D2: 1 | E2: 1 | F2: 20
A3: 基础属性 | B3: 技巧 | C3: 10 | D3: 1 | E3: 1 | F3: 20
A4: 基础属性 | B4: 根骨 | C4: 10 | D4: 1 | E4: 1 | F4: 20
A5: 基础属性 | B5: 内息 | C5: 10 | D5: 1 | E5: 1 | F5: 20
A6: 基础属性 | B6: 身法 | C6: 10 | D6: 1 | E6: 1 | F6: 20
A7: 基础属性 | B7: 定力 | C7: 10 | D7: 1 | E7: 1 | F7: 20
A8: 二级属性 | B8: 攻击 | C8: 100 | D8: 20 | F8: 490
A9: 二级属性 | B9: 防御 | C9: 100 | D9: 20 | F9: 1456
A10: 二级属性 | B10: 速度 | C10: 20 | D10: 5 | F10: 540
A11: 二级属性 | B11: 命中 | C11: 20 | D11: 5 | F11: 590
A12: 二级属性 | B12: 招架 | C12: 20 | D12: 5 | F12: 440
A13: 二级属性 | B13: 偏斜 | C13: 20 | D13: 5 | F13: 820
A14: 二级属性 | B14: 抵抗 | C14: 0 | D14: 0
A15: 二级属性 | B15: 韧性 | C15: 0 | D15: 0
A16: 二级属性 | B16: 气血 | C16: 500 | D16: 100 | F16: 3040
A17: 二级属性 | B17: 内力 | C17: 200 | D17: 40 | F17: 1650
A18: 二级属性 | B18: 内力回复 | C18: 10 | D18: 2 | F18: 75
A19: 二级属性 | B19: 气血恢复 | C19: 10 | D19: 1
A20: 三级属性 | B20: 免伤 | C20: 0
A21: 三级属性 | B21: 招架率 | C21: 0.46418338
A22: 三级属性 | B22: 偏斜率 | C22: 0.46043165
A23: 三级属性 | B23: 抵抗效果
A24: 三级属性 | B24: 免伤率
A25: 三级属性 | B25: 防御免伤率 | C25: 0.42555147

Sheet Coefficients
A1: 角色 | B1: 属性名 | C1: 基础数值系数 | D1: 成长系数 | E1: 资质系数 | F1: 经脉系数
A2: 青槐 | B2: 臂力 | C2: 1 | D2: 1 | E2: 1 | F2: 1
A3: 青槐 | B3: 技巧 | C3: 1 | D3: 1 | E3: 1 | F3: 1
A4: 青槐 | B4: 根骨 | C4: 1 | D4: 1 | E4: 1 | F4: 1
A5: 青槐 | B5: 内息 | C5: 1 | D5: 1 | E5: 1 | F5: 1
A6: 青槐 | B6: 身法 | C6: 1 | D6: 1 | E6: 1 | F6: 1
A7: 青槐 | B7: 定力 | C7: 1 | D7: 1 | E7: 1 | F7: 1
A8: 青槐 | B8: 攻击 | C8: 1 | D8: 1 | E8: 1 | F8: 1
A9: 青槐 | B9: 防御 | C9: 1 | D9: 1 | E9: 1 | F9: 1
A10: 青槐 | B10: 速度 | C10: 1 | D10: 1 | E10: 1 | F10: 1
A11: 青槐 | B11: 命中 | C11: 1 | D11: 1 | E11: 1 | F11: 1
A12: 青槐 | B12: 招架 | C12: 1 | D12: 1 | E12: 1 | F12: 1
A13: 青槐 | B13: 偏斜 | C13: 1 | D13: 1 | E13: 1 | F13: 1
... A49: 新角色 | B49: 防御免伤率 | C49: 1 | D49: 1 | E49: 1 | F49: 1

Sheet EquipPlans
A1: 装备方案 | B1: 属性名 | C1: 武器 | D1: 护甲 | E1: 护腰 | F1: 护腕 | G1: 戒指 | H1: 吊坠 | I1: 装备合计
A2: 标准测试装 | B2: 攻击 | C2: 1000 | I2: =SUM(C2:H2)
A3: 标准测试装 | B3: 防御 | D3: 1000 | E3: 500 | H3: 500 | I3: =SUM(C3:H3)
A4: 标准测试装 | B4: 速度 | E4: 150 | G4: 150 | I4: =SUM(C4:H4)
A5: 标准测试装 | B5: 命中 | C5: 250 | F5: 150 | G5: 150 | I5: =SUM(C5:H5)
A6: 标准测试装 | B6: 招架 | F6: 150 | I6: =SUM(C6:H6)
A7: 标准测试装 | B7: 偏斜 | H7: 150 | I7: =SUM(C7:H7)
A8: 标准测试装 | B8: 气血 | D8: 5000 | I8: =SUM(C8:H8)

Sheet TestCases
A1: 测试ID | B1: 角色 | C1: 装备方案 | D1: 等级 | E1: 备注
A2: T001 | B2: 青槐 | C2: 标准测试装 | D2: 100 | E2: 基准
A3: T002 | B3: 新角色 | C3: 标准测试装 | D3: 100 | E3: 修改系数看变化

Sheet Results
A1: 测试ID | B1: 角色 | C1: 装备方案 | D1: 臂力 | E1: 技巧 | F1: 根骨 | G1: 内息 | H1: 身法 | I1: 定力 | J1: 攻击 | K1: 防御 | L1: 速度 | M1: 命中 | N1: 招架 | O1: 偏斜 | P1: 抵抗 | Q1: 韧性 | R1: 气血 | S1: 内力 | T1: 内力回复 | U1: 气血恢复 | V1: 招架率 | W1: 偏斜率 | X1: 防御免伤率
A2: =IF(TestCases!A2="","",TestCases!A2) | B2: =IF($A2="","",TestCases!B2) | C2: =IF($A2="","",TestCases!C2) | D2: =IF($A2="","",SUMIFS(StandardParams!$C:$C,StandardParams!$B:$B,"臂力")*IFERROR(SUMIFS(Coefficients!$C:$C,Coefficients!$A:$A,$B2,Coefficients!$B:$B,"臂力"),1)+SUMIFS(StandardParams!$D:$D,StandardParams!$B:$B,"臂力")*IFERROR(SUMIFS(Coefficients!$D:$D,Coefficients!$A:$A,$B2,Coefficients!$B:$B,"臂力"),1)*SUMIFS(TestCases!$D:$D,TestCases!$A:$A,$A2)*SUMIFS(StandardParams!$E:$E,StandardParams!$B:$B,"臂力")*IFERROR(SUMIFS(Coefficients!$E:$E,Coefficients!$A:$A,$B2,Coefficients!$B:$B,"臂力"),1)+SUMIFS(StandardParams!$F:$F,StandardParams!$B:$B,"臂力")*IFERROR(SUMIFS(Coefficients!$F:$F,Coefficients!$A:$A,$B2,Coefficients!$B:$B,"臂力"),1)) | E2: =IF($A2="","",SUMIFS(StandardParams!$C:$C,StandardParams!$B:$B,"技巧")*IFERROR(SUMIFS(Coefficients!$C:$C,Coefficients!$A:$A,$B2,Coefficients!$B:$B,"技巧"),1)+SUMIFS(StandardParams!$D:$D,StandardParams!$B:$B,"技巧")*IFERROR(SUMIFS(Coefficients!$D:$D,Coefficients!$A:$A,$B2,Coefficients!$B:$B,"技巧"),1)*SUMIFS(TestCases!$D:$D,TestCases!$A:$A,$A2)*SUMIFS(StandardParams!$E:$E,StandardParams!$B:$B,"技巧")*IFERROR(SUMIFS(Coefficients!$E:$E,Coefficients!$A:$A,$B2,Coefficients!$B:$B,"技巧"),1)+SUMIFS(StandardParams!$F:$F,StandardParams!$B:$B,"技巧")*IFERROR(SUMIFS(Coefficients!$F:$F,Coefficients!$A:$A,$B2,Coefficients!$B:$B,"技巧"),1)) | F2: =IF($A2="","",SUMIFS(StandardParams!$C:$C,StandardParams!$B:$B,"根骨")*IFERROR(SUMIFS(Coefficients!$C:$C,Coefficients!$A:$A,$B2,Coefficients!$B:$B,"根骨"),1)+SUMIFS(StandardParams!$D:$D,StandardParams!$B:$B,"根骨")*IFERROR(SUMIFS(Coefficients!$D:$D,Coefficients!$A:$A,$B2,Coefficients!$B:$B,"根骨"),1)*SUMIFS(TestCases!$D:$D,TestCases!$A:$A,$A2)*SUMIFS(StandardParams!$E:$E,StandardParams!$B:$B,"根骨")*IFERROR(SUMIFS(Coefficients!$E:$E,Coefficients!$A:$A,$B2,Coefficients!$B:$B,"根骨"),1)+SUMIFS(StandardParams!$F:$F,StandardParams!$B:$B,"根骨")*IFERROR(SUMIFS(Coefficients!$F:$F,Coefficients!$A:$A,$B2,Coefficients!$B:$B,"根骨"),1)) | G2: =IF($A2="","",SUMIFS(StandardParams!$C:$C,StandardParams!$B:$B,"内息")*IFERROR(SUMIFS(Coefficients!$C:$C,Coefficients!$A:$A,$B2,Coefficients!$B:$B,"内息"),1)+SUMIFS(StandardParams!$D:$D,StandardParams!$B:$B,"内息")*IFERROR(SUMIFS(Coefficients!$D:$D,Coefficients!$A:$A,$B2,Coefficients!$B:$B,"内息"),1)*SUMIFS(TestCases!$D:$D,TestCases!$A:$A,$A2)*SUMIFS(StandardParams!$E:$E,StandardParams!$B:$B,"内息")*IFERROR(SUMIFS(Coefficients!$E:$E,Coefficients!$A:$A,$B2,Coefficients!$B:$B,"内息"),1)+SUMIFS(StandardParams!$F:$F,StandardParams!$B:$B,"内息")*IFERROR(SUMIFS(Coefficients!$F:$F,Coefficients!$A:$A,$B2,Coefficients!$B:$B,"内息"),1)) | H2: =IF($A2="","",SUMIFS(StandardParams!$C:$C,StandardParams!$B:$B,"身法")*IFERROR(SUMIFS(Coefficients!$C:$C,Coefficients!$A:$A,$B2,Coefficients!$B:$B,"身法"),1)+SUMIFS(StandardParams!$D:$D,StandardParams!$B:$B,"身法")*IFERROR(SUMIFS(Coefficients!$D:$D,Coefficients!$A:$A,$B2,Coefficients!$B:$B,"身法"),1)*SUMIFS(TestCases!$D:$D,TestCases!$A:$A,$A2)*SUMIFS(StandardParams!$E:$E,StandardParams!$B:$B,"身法")*IFERROR(SUMIFS(Coefficients!$E:$E,Coefficients!$A:$A,$B2,Coefficients!$B:$B,"身法"),1)+SUMIFS(StandardParams!$F:$F,StandardParams!$B:$B,"身法")*IFERROR(SUMIFS(Coefficients!$F:$F,Coefficients!$A:$A,$B2,Coefficients!$B:$B,"身法"),1)) | I2: =IF($A2="","",SUMIFS(StandardParams!$C:$C,StandardParams!$B:$B,"定力")*IFERROR(SUMIFS(Coefficients!$C:$C,Coefficients!$A:$A,$B2,Coefficients!$B:$B,"定力"),1)+SUMIFS(StandardParams!$D:$D,StandardParams!$B:$B,"定力")*IFERROR(SUMIFS(Coefficients!$D:$D,Coefficients!$A:$A,$B2,Coefficients!$B:$B,"定力"),1)*SUMIFS(TestCases!$D:$D,TestCases!$A:$A,$A2)*SUMIFS(StandardParams!$E:$E,StandardParams!$B:$B,"定力")*IFERROR(SUMIFS(Coefficients!$E:$E,Coefficients!$A:$A,$B2,Coefficients!$B:$B,"定力"),1)+SUMIFS(StandardParams!$F:$F,StandardParams!$B:$B,"定力")*IFERROR(SUMIFS(Coefficients!$F:$F,Coefficients!$A:$A,$B2,Coefficients!$B:$B,"定力"),1)) | J2: =IF($A2="","",SUMIFS(StandardParams!$C:$C,StandardParams!$B:$B,"攻击")*IFERROR(SUMIFS(Coefficients!$C:$C,Coefficients!$A:$A,$B2,Coefficients!$B:$B,"攻击"),1)+SUMIFS(StandardParams!$D:$D,StandardParams!$B:$B,"攻击")*IFERROR(SUMIFS(Coefficients!$D:$D,Coefficients!$A:$A,$B2,Coefficients!$B:$B,"攻击"),1)*SUMIFS(TestCases!$D:$D,TestCases!$A:$A,$A2)+SUMIFS(StandardParams!$F:$F,StandardParams!$B:$B,"攻击")*IFERROR(SUMIFS(Coefficients!$F:$F,Coefficients!$A:$A,$B2,Coefficients!$B:$B,"攻击"),1)+SUMIFS(EquipPlans!$I:$I,EquipPlans!$A:$A,$C2,EquipPlans!$B:$B,"攻击")+D2*4) | K2: =IF($A2="","",SUMIFS(StandardParams!$C:$C,StandardParams!$B:$B,"防御")*IFERROR(SUMIFS(Coefficients!$C:$C,Coefficients!$A:$A,$B2,Coefficients!$B:$B,"防御"),1)+SUMIFS(StandardParams!$D:$D,StandardParams!$B:$B,"防御")*IFERROR(SUMIFS(Coefficients!$D:$D,Coefficients!$A:$A,$B2,Coefficients!$B:$B,"防御"),1)*SUMIFS(TestCases!$D:$D,TestCases!$A:$A,$A2)+SUMIFS(StandardParams!$F:$F,StandardParams!$B:$B,"防御")*IFERROR(SUMIFS(Coefficients!$F:$F,Coefficients!$A:$A,$B2,Coefficients!$B:$B,"防御"),1)+SUMIFS(EquipPlans!$I:$I,EquipPlans!$A:$A,$C2,EquipPlans!$B:$B,"防御")) | L2: =IF($A2="","",SUMIFS(StandardParams!$C:$C,StandardParams!$B:$B,"速度")*IFERROR(SUMIFS(Coefficients!$C:$C,Coefficients!$A:$A,$B2,Coefficients!$B:$B,"速度"),1)+SUMIFS(StandardParams!$D:$D,StandardParams!$B:$B,"速度")*IFERROR(SUMIFS(Coefficients!$D:$D,Coefficients!$A:$A,$B2,Coefficients!$B:$B,"速度"),1)*SUMIFS(TestCases!$D:$D,TestCases!$A:$A,$A2)+SUMIFS(StandardParams!$F:$F,StandardParams!$B:$B,"速度")*IFERROR(SUMIFS(Coefficients!$F:$F,Coefficients!$A:$A,$B2,Coefficients!$B:$B,"速度"),1)+SUMIFS(EquipPlans!$I:$I,EquipPlans!$A:$A,$C2,EquipPlans!$B:$B,"速度")+H2*2) | M2: =IF($A2="","",SUMIFS(StandardParams!$C:$C,StandardParams!$B:$B,"命中")*IFERROR(SUMIFS(Coefficients!$C:$C,Coefficients!$A:$A,$B2,Coefficients!$B:$B,"命中"),1)+SUMIFS(StandardParams!$D:$D,StandardParams!$B:$B,"命中")*IFERROR(SUMIFS(Coefficients!$D:$D,Coefficients!$A:$A,$B2,Coefficients!$B:$B,"命中"),1)*SUMIFS(TestCases!$D:$D,TestCases!$A:$A,$A2)+SUMIFS(StandardParams!$F:$F,StandardParams!$B:$B,"命中")*IFERROR(SUMIFS(Coefficients!$F:$F,Coefficients!$A:$A,$B2,Coefficients!$B:$B,"命中"),1)+SUMIFS(EquipPlans!$I:$I,EquipPlans!$A:$A,$C2,EquipPlans!$B:$B,"命中")+E2*2) | N2: =IF($A2="","",SUMIFS(StandardParams!$C:$C,StandardParams!$B:$B,"招架")*IFERROR(SUMIFS(Coefficients!$C:$C,Coefficients!$A:$A,$B2,Coefficients!$B:$B,"招架"),1)+SUMIFS(StandardParams!$D:$D,StandardParams!$B:$B,"招架")*IFERROR(SUMIFS(Coefficients!$D:$D,Coefficients!$A:$A,$B2,Coefficients!$B:$B,"招架"),1)*SUMIFS(TestCases!$D:$D,TestCases!$A:$A,$A2)+SUMIFS(StandardParams!$F:$F,StandardParams!$B:$B,"招架")*IFERROR(SUMIFS(Coefficients!$F:$F,Coefficients!$A:$A,$B2,Coefficients!$B:$B,"招架"),1)+SUMIFS(EquipPlans!$I:$I,EquipPlans!$A:$A,$C2,EquipPlans!$B:$B,"招架")+E2*2) | O2: =IF($A2="","",SUMIFS(StandardParams!$C:$C,StandardParams!$B:$B,"偏斜")*IFERROR(SUMIFS(Coefficients!$C:$C,Coefficients!$A:$A,$B2,Coefficients!$B:$B,"偏斜"),1)+SUMIFS(StandardParams!$D:$D,StandardParams!$B:$B,"偏斜")*IFERROR(SUMIFS(Coefficients!$D:$D,Coefficients!$A:$A,$B2,Coefficients!$B:$B,"偏斜"),1)*SUMIFS(TestCases!$D:$D,TestCases!$A:$A,$A2)+SUMIFS(StandardParams!$F:$F,StandardParams!$B:$B,"偏斜")*IFERROR(SUMIFS(Coefficients!$F:$F,Coefficients!$A:$A,$B2,Coefficients!$B:$B,"偏斜"),1)+SUMIFS(EquipPlans!$I:$I,EquipPlans!$A:$A,$C2,EquipPlans!$B:$B,"偏斜")+H2*2) | P2: =IF($A2="","",SUMIFS(StandardParams!$C:$C,StandardParams!$B:$B,"抵抗")*IFERROR(SUMIFS(Coefficients!$C:$C,Coefficients!$A:$A,$B2,Coefficients!$B:$B,"抵抗"),1)+SUMIFS(StandardParams!$D:$D,StandardParams!$B:$B,"抵抗")*IFERROR(SUMIFS(Coefficients!$D:$D,Coefficients!$A:$A,$B2,Coefficients!$B:$B,"抵抗"),1)*SUMIFS(TestCases!$D:$D,TestCases!$A:$A,$A2)+SUMIFS(StandardParams!$F:$F,StandardParams!$B:$B,"抵抗")*IFERROR(SUMIFS(Coefficients!$F:$F,Coefficients!$A:$A,$B2,Coefficients!$B:$B,"抵抗"),1)+SUMIFS(EquipPlans!$I:$I,EquipPlans!$A:$A,$C2,EquipPlans!$B:$B,"抵抗")+I2*2.5) | Q2: =IF($A2="","",SUMIFS(StandardParams!$C:$C,StandardParams!$B:$B,"韧性")*IFERROR(SUMIFS(Coefficients!$C:$C,Coefficients!$A:$A,$B2,Coefficients!$B:$B,"韧性"),1)+SUMIFS(StandardParams!$D:$D,StandardParams!$B:$B,"韧性")*IFERROR(SUMIFS(Coefficients!$D:$D,Coefficients!$A:$A,$B2,Coefficients!$B:$B,"韧性"),1)*SUMIFS(TestCases!$D:$D,TestCases!$A:$A,$A2)+SUMIFS(StandardParams!$F:$F,StandardParams!$B:$B,"韧性")*IFERROR(SUMIFS(Coefficients!$F:$F,Coefficients!$A:$A,$B2,Coefficients!$B:$B,"韧性"),1)+SUMIFS(EquipPlans!$I:$I,EquipPlans!$A:$A,$C2,EquipPlans!$B:$B,"韧性")+F2) | R2: =IF($A2="","",SUMIFS(StandardParams!$C:$C,StandardParams!$B:$B,"气血")*IFERROR(SUMIFS(Coefficients!$C:$C,Coefficients!$A:$A,$B2,Coefficients!$B:$B,"气血"),1)+SUMIFS(StandardParams!$D:$D,StandardParams!$B:$B,"气血")*IFERROR(SUMIFS(Coefficients!$D:$D,Coefficients!$A:$A,$B2,Coefficients!$B:$B,"气血"),1)*SUMIFS(TestCases!$D:$D,TestCases!$A:$A,$A2)+SUMIFS(StandardParams!$F:$F,StandardParams!$B:$B,"气血")*IFERROR(SUMIFS(Coefficients!$F:$F,Coefficients!$A:$A,$B2,Coefficients!$B:$B,"气血"),1)+SUMIFS(EquipPlans!$I:$I,EquipPlans!$A:$A,$C2,EquipPlans!$B:$B,"气血")+F2*20) | S2: =IF($A2="","",SUMIFS(StandardParams!$C:$C,StandardParams!$B:$B,"内力")*IFERROR(SUMIFS(Coefficients!$C:$C,Coefficients!$A:$A,$B2,Coefficients!$B:$B,"内力"),1)+SUMIFS(StandardParams!$D:$D,StandardParams!$B:$B,"内力")*IFERROR(SUMIFS(Coefficients!$D:$D,Coefficients!$A:$A,$B2,Coefficients!$B:$B,"内力"),1)*SUMIFS(TestCases!$D:$D,TestCases!$A:$A,$A2)+SUMIFS(StandardParams!$F:$F,StandardParams!$B:$B,"内力")*IFERROR(SUMIFS(Coefficients!$F:$F,Coefficients!$A:$A,$B2,Coefficients!$B:$B,"内力"),1)+SUMIFS(EquipPlans!$I:$I,EquipPlans!$A:$A,$C2,EquipPlans!$B:$B,"内力")+G2*10) | T2: =IF($A2="","",SUMIFS(StandardParams!$C:$C,StandardParams!$B:$B,"内力回复")*IFERROR(SUMIFS(Coefficients!$C:$C,Coefficients!$A:$A,$B2,Coefficients!$B:$B,"内力回复"),1)+SUMIFS(StandardParams!$D:$D,StandardParams!$B:$B,"内力回复")*IFERROR(SUMIFS(Coefficients!$D:$D,Coefficients!$A:$A,$B2,Coefficients!$B:$B,"内力回复"),1)*SUMIFS(TestCases!$D:$D,TestCases!$A:$A,$A2)+SUMIFS(StandardParams!$F:$F,StandardParams!$B:$B,"内力回复")*IFERROR(SUMIFS(Coefficients!$F:$F,Coefficients!$A:$A,$B2,Coefficients!$B:$B,"内力回复"),1)+SUMIFS(EquipPlans!$I:$I,EquipPlans!$A:$A,$C2,EquipPlans!$B:$B,"内力回复")+G2*0.5) | U2: =IF($A2="","",SUMIFS(StandardParams!$C:$C,StandardParams!$B:$B,"气血恢复")*IFERROR(SUMIFS(Coefficients!$C:$C,Coefficients!$A:$A,$B2,Coefficients!$B:$B,"气血恢复"),1)+SUMIFS(StandardParams!$D:$D,StandardParams!$B:$B,"气血恢复")*IFERROR(SUMIFS(Coefficients!$D:$D,Coefficients!$A:$A,$B2,Coefficients!$B:$B,"气血恢复"),1)*SUMIFS(TestCases!$D:$D,TestCases!$A:$A,$A2)+SUMIFS(StandardParams!$F:$F,StandardParams!$B:$B,"气血恢复")*IFERROR(SUMIFS(Coefficients!$F:$F,Coefficients!$A:$A,$B2,Coefficients!$B:$B,"气血恢复"),1)+SUMIFS(EquipPlans!$I:$I,EquipPlans!$A:$A,$C2,EquipPlans!$B:$B,"气血恢复")) | V2: =IF($A2="","",L2/(N2+L2+500)) | W2: =IF($A2="","",M2/(O2+M2+500)) | X2: =IF($A2="","",K2/(J2+K2))
A3: =IF(TestCases!A3="","",TestCases!A3) | B3: =IF($A3="","",TestCases!B3) | C3: =IF($A3="","",TestCases!C3) | D3: =IF($A3="","",SUMIFS(StandardParams!$C:$C,StandardParams!$B:$B,"臂力")*IFERROR(SUMIFS(Coefficients!$C:$C,Coefficients!$A:$A,$B3,Coefficients!$B:$B,"臂力"),1)+SUMIFS(StandardParams!$D:$D,StandardParams!$B:$B,"臂力")*IFERROR(SUMIFS(Coefficients!$D:$D,Coefficients!$A:$A,$B3,Coefficients!$B:$B,"臂力"),1)*SUMIFS(TestCases!$D:$D,TestCases!$A:$A,$A3)*SUMIFS(StandardParams!$E:$E,StandardParams!$B:$B,"臂力")*IFERROR(SUMIFS(Coefficients!$E:$E,Coefficients!$A:$A,$B3,Coefficients!$B:$B,"臂力"),1)+SUMIFS(StandardParams!$F:$F,StandardParams!$B:$B,"臂力")*IFERROR(SUMIFS(Coefficients!$F:$F,Coefficients!$A:$A,$B3,Coefficients!$B:$B,"臂力"),1)) | E3: =IF($A3="","",SUMIFS(StandardParams!$C:$C,StandardParams!$B:$B,"技巧")*IFERROR(SUMIFS(Coefficients!$C:$C,Coefficients!$A:$A,$B3,Coefficients!$B:$B,"技巧"),1)+SUMIFS(StandardParams!$D:$D,StandardParams!$B:$B,"技巧")*IFERROR(SUMIFS(Coefficients!$D:$D,Coefficients!$A:$A,$B3,Coefficients!$B:$B,"技巧"),1)*SUMIFS(TestCases!$D:$D,TestCases!$A:$A,$A3)*SUMIFS(StandardParams!$E:$E,StandardParams!$B:$B,"技巧")*IFERROR(SUMIFS(Coefficients!$E:$E,Coefficients!$A:$A,$B3,Coefficients!$B:$B,"技巧"),1)+SUMIFS(StandardParams!$F:$F,StandardParams!$B:$B,"技巧")*IFERROR(SUMIFS(Coefficients!$F:$F,Coefficients!$A:$A,$B3,Coefficients!$B:$B,"技巧"),1)) | F3: =IF($A3="","",SUMIFS(StandardParams!$C:$C,StandardParams!$B:$B,"根骨")*IFERROR(SUMIFS(Coefficients!$C:$C,Coefficients!$A:$A,$B3,Coefficients!$B:$B,"根骨"),1)+SUMIFS(StandardParams!$D:$D,StandardParams!$B:$B,"根骨")*IFERROR(SUMIFS(Coefficients!$D:$D,Coefficients!$A:$A,$B3,Coefficients!$B:$B,"根骨"),1)*SUMIFS(TestCases!$D:$D,TestCases!$A:$A,$A3)*SUMIFS(StandardParams!$E:$E,StandardParams!$B:$B,"根骨")*IFERROR(SUMIFS(Coefficients!$E:$E,Coefficients!$A:$A,$B3,Coefficients!$B:$B,"根骨"),1)+SUMIFS(StandardParams!$F:$F,StandardParams!$B:$B,"根骨")*IFERROR(SUMIFS(Coefficients!$F:$F,Coefficients!$A:$A,$B3,Coefficients!$B:$B,"根骨"),1)) | G3: =IF($A3="","",SUMIFS(StandardParams!$C:$C,StandardParams!$B:$B,"内息")*IFERROR(SUMIFS(Coefficients!$C:$C,Coefficients!$A:$A,$B3,Coefficients!$B:$B,"内息"),1)+SUMIFS(StandardParams!$D:$D,StandardParams!$B:$B,"内息")*IFERROR(SUMIFS(Coefficients!$D:$D,Coefficients!$A:$A,$B3,Coefficients!$B:$B,"内息"),1)*SUMIFS(TestCases!$D:$D,TestCases!$A:$A,$A3)*SUMIFS(StandardParams!$E:$E,StandardParams!$B:$B,"内息")*IFERROR(SUMIFS(Coefficients!$E:$E,Coefficients!$A:$A,$B3,Coefficients!$B:$B,"内息"),1)+SUMIFS(StandardParams!$F:$F,StandardParams!$B:$B,"内息")*IFERROR(SUMIFS(Coefficients!$F:$F,Coefficients!$A:$A,$B3,Coefficients!$B:$B,"内息"),1)) | H3: =IF($A3="","",SUMIFS(StandardParams!$C:$C,StandardParams!$B:$B,"身法")*IFERROR(SUMIFS(Coefficients!$C:$C,Coefficients!$A:$A,$B3,Coefficients!$B:$B,"身法"),1)+SUMIFS(StandardParams!$D:$D,StandardParams!$B:$B,"身法")*IFERROR(SUMIFS(Coefficients!$D:$D,Coefficients!$A:$A,$B3,Coefficients!$B:$B,"身法"),1)*SUMIFS(TestCases!$D:$D,TestCases!$A:$A,$A3)*SUMIFS(StandardParams!$E:$E,StandardParams!$B:$B,"身法")*IFERROR(SUMIFS(Coefficients!$E:$E,Coefficients!$A:$A,$B3,Coefficients!$B:$B,"身法"),1)+SUMIFS(StandardParams!$F:$F,StandardParams!$B:$B,"身法")*IFERROR(SUMIFS(Coefficients!$F:$F,Coefficients!$A:$A,$B3,Coefficients!$B:$B,"身法"),1)) | I3: =IF($A3="","",SUMIFS(StandardParams!$C:$C,StandardParams!$B:$B,"定力")*IFERROR(SUMIFS(Coefficients!$C:$C,Coefficients!$A:$A,$B3,Coefficients!$B:$B,"定力"),1)+SUMIFS(StandardParams!$D:$D,StandardParams!$B:$B,"定力")*IFERROR(SUMIFS(Coefficients!$D:$D,Coefficients!$A:$A,$B3,Coefficients!$B:$B,"定力"),1)*SUMIFS(TestCases!$D:$D,TestCases!$A:$A,$A3)*SUMIFS(StandardParams!$E:$E,StandardParams!$B:$B,"定力")*IFERROR(SUMIFS(Coefficients!$E:$E,Coefficients!$A:$A,$B3,Coefficients!$B:$B,"定力"),1)+SUMIFS(StandardParams!$F:$F,StandardParams!$B:$B,"定力")*IFERROR(SUMIFS(Coefficients!$F:$F,Coefficients!$A:$A,$B3,Coefficients!$B:$B,"定力"),1)) | J3: =IF($A3="","",SUMIFS(StandardParams!$C:$C,StandardParams!$B:$B,"攻击")*IFERROR(SUMIFS(Coefficients!$C:$C,Coefficients!$A:$A,$B3,Coefficients!$B:$B,"攻击"),1)+SUMIFS(StandardParams!$D:$D,StandardParams!$B:$B,"攻击")*IFERROR(SUMIFS(Coefficients!$D:$D,Coefficients!$A:$A,$B3,Coefficients!$B:$B,"攻击"),1)*SUMIFS(TestCases!$D:$D,TestCases!$A:$A,$A3)+SUMIFS(StandardParams!$F:$F,StandardParams!$B:$B,"攻击")*IFERROR(SUMIFS(Coefficients!$F:$F,Coefficients!$A:$A,$B3,Coefficients!$B:$B,"攻击"),1)+SUMIFS(EquipPlans!$I:$I,EquipPlans!$A:$A,$C3,EquipPlans!$B:$B,"攻击")+D3*4) | K3: =IF($A3="","",SUMIFS(StandardParams!$C:$C,StandardParams!$B:$B,"防御")*IFERROR(SUMIFS(Coefficients!$C:$C,Coefficients!$A:$A,$B3,Coefficients!$B:$B,"防御"),1)+SUMIFS(StandardParams!$D:$D,StandardParams!$B:$B,"防御")*IFERROR(SUMIFS(Coefficients!$D:$D,Coefficients!$A:$A,$B3,Coefficients!$B:$B,"防御"),1)*SUMIFS(TestCases!$D:$D,TestCases!$A:$A,$A3)+SUMIFS(StandardParams!$F:$F,StandardParams!$B:$B,"防御")*IFERROR(SUMIFS(Coefficients!$F:$F,Coefficients!$A:$A,$B3,Coefficients!$B:$B,"防御"),1)+SUMIFS(EquipPlans!$I:$I,EquipPlans!$A:$A,$C3,EquipPlans!$B:$B,"防御")) | L3: =IF($A3="","",SUMIFS(StandardParams!$C:$C,StandardParams!$B:$B,"速度")*IFERROR(SUMIFS(Coefficients!$C:$C,Coefficients!$A:$A,$B3,Coefficients!$B:$B,"速度"),1)+SUMIFS(StandardParams!$D:$D,StandardParams!$B:$B,"速度")*IFERROR(SUMIFS(Coefficients!$D:$D,Coefficients!$A:$A,$B3,Coefficients!$B:$B,"速度"),1)*SUMIFS(TestCases!$D:$D,TestCases!$A:$A,$A3)+SUMIFS(StandardParams!$F:$F,StandardParams!$B:$B,"速度")*IFERROR(SUMIFS(Coefficients!$F:$F,Coefficients!$A:$A,$B3,Coefficients!$B:$B,"速度"),1)+SUMIFS(EquipPlans!$I:$I,EquipPlans!$A:$A,$C3,EquipPlans!$B:$B,"速度")+H3*2) | M3: =IF($A3="","",SUMIFS(StandardParams!$C:$C,StandardParams!$B:$B,"命中")*IFERROR(SUMIFS(Coefficients!$C:$C,Coefficients!$A:$A,$B3,Coefficients!$B:$B,"命中"),1)+SUMIFS(StandardParams!$D:$D,StandardParams!$B:$B,"命中")*IFERROR(SUMIFS(Coefficients!$D:$D,Coefficients!$A:$A,$B3,Coefficients!$B:$B,"命中"),1)*SUMIFS(TestCases!$D:$D,TestCases!$A:$A,$A3)+SUMIFS(StandardParams!$F:$F,StandardParams!$B:$B,"命中")*IFERROR(SUMIFS(Coefficients!$F:$F,Coefficients!$A:$A,$B3,Coefficients!$B:$B,"命中"),1)+SUMIFS(EquipPlans!$I:$I,EquipPlans!$A:$A,$C3,EquipPlans!$B:$B,"命中")+E3*2) | N3: =IF($A3="","",SUMIFS(StandardParams!$C:$C,StandardParams!$B:$B,"招架")*IFERROR(SUMIFS(Coefficients!$C:$C,Coefficients!$A:$A,$B3,Coefficients!$B:$B,"招架"),1)+SUMIFS(StandardParams!$D:$D,StandardParams!$B:$B,"招架")*IFERROR(SUMIFS(Coefficients!$D:$D,Coefficients!$A:$A,$B3,Coefficients!$B:$B,"招架"),1)*SUMIFS(TestCases!$D:$D,TestCases!$A:$A,$A3)+SUMIFS(StandardParams!$F:$F,StandardParams!$B:$B,"招架")*IFERROR(SUMIFS(Coefficients!$F:$F,Coefficients!$A:$A,$B3,Coefficients!$B:$B,"招架"),1)+SUMIFS(EquipPlans!$I:$I,EquipPlans!$A:$A,$C3,EquipPlans!$B:$B,"招架")+E3*2) | O3: =IF($A3="","",SUMIFS(StandardParams!$C:$C,StandardParams!$B:$B,"偏斜")*IFERROR(SUMIFS(Coefficients!$C:$C,Coefficients!$A:$A,$B3,Coefficients!$B:$B,"偏斜"),1)+SUMIFS(StandardParams!$D:$D,StandardParams!$B:$B,"偏斜")*IFERROR(SUMIFS(Coefficients!$D:$D,Coefficients!$A:$A,$B3,Coefficients!$B:$B,"偏斜"),1)*SUMIFS(TestCases!$D:$D,TestCases!$A:$A,$A3)+SUMIFS(StandardParams!$F:$F,StandardParams!$B:$B,"偏斜")*IFERROR(SUMIFS(Coefficients!$F:$F,Coefficients!$A:$A,$B3,Coefficients!$B:$B,"偏斜"),1)+SUMIFS(EquipPlans!$I:$I,EquipPlans!$A:$A,$C3,EquipPlans!$B:$B,"偏斜")+H3*2) | P3: =IF($A3="","",SUMIFS(StandardParams!$C:$C,StandardParams!$B:$B,"抵抗")*IFERROR(SUMIFS(Coefficients!$C:$C,Coefficients!$A:$A,$B3,Coefficients!$B:$B,"抵抗"),1)+SUMIFS(StandardParams!$D:$D,StandardParams!$B:$B,"抵抗")*IFERROR(SUMIFS(Coefficients!$D:$D,Coefficients!$A:$A,$B3,Coefficients!$B:$B,"抵抗"),1)*SUMIFS(TestCases!$D:$D,TestCases!$A:$A,$A3)+SUMIFS(StandardParams!$F:$F,StandardParams!$B:$B,"抵抗")*IFERROR(SUMIFS(Coefficients!$F:$F,Coefficients!$A:$A,$B3,Coefficients!$B:$B,"抵抗"),1)+SUMIFS(EquipPlans!$I:$I,EquipPlans!$A:$A,$C3,EquipPlans!$B:$B,"抵抗")+I3*2.5) | Q3: =IF($A3="","",SUMIFS(StandardParams!$C:$C,StandardParams!$B:$B,"韧性")*IFERROR(SUMIFS(Coefficients!$C:$C,Coefficients!$A:$A,$B3,Coefficients!$B:$B,"韧性"),1)+SUMIFS(StandardParams!$D:$D,StandardParams!$B:$B,"韧性")*IFERROR(SUMIFS(Coefficients!$D:$D,Coefficients!$A:$A,$B3,Coefficients!$B:$B,"韧性"),1)*SUMIFS(TestCases!$D:$D,TestCases!$A:$A,$A3)+SUMIFS(StandardParams!$F:$F,StandardParams!$B:$B,"韧性")*IFERROR(SUMIFS(Coefficients!$F:$F,Coefficients!$A:$A,$B3,Coefficients!$B:$B,"韧性"),1)+SUMIFS(EquipPlans!$I:$I,EquipPlans!$A:$A,$C3,EquipPlans!$B:$B,"韧性")+F3) | R3: =IF($A3="","",SUMIFS(StandardParams!$C:$C,StandardParams!$B:$B,"气血")*IFERROR(SUMIFS(Coefficients!$C:$C,Coefficients!$A:$A,$B3,Coefficients!$B:$B,"气血"),1)+SUMIFS(StandardParams!$D:$D,StandardParams!$B:$B,"气血")*IFERROR(SUMIFS(Coefficients!$D:$D,Coefficients!$A:$A,$B3,Coefficients!$B:$B,"气血"),1)*SUMIFS(TestCases!$D:$D,TestCases!$A:$A,$A3)+SUMIFS(StandardParams!$F:$F,StandardParams!$B:$B,"气血")*IFERROR(SUMIFS(Coefficients!$F:$F,Coefficients!$A:$A,$B3,Coefficients!$B:$B,"气血"),1)+SUMIFS(EquipPlans!$I:$I,EquipPlans!$A:$A,$C3,EquipPlans!$B:$B,"气血")+F3*20) | S3: =IF($A3="","",SUMIFS(StandardParams!$C:$C,StandardParams!$B:$B,"内力")*IFERROR(SUMIFS(Coefficients!$C:$C,Coefficients!$A:$A,$B3,Coefficients!$B:$B,"内力"),1)+SUMIFS(StandardParams!$D:$D,StandardParams!$B:$B,"内力")*IFERROR(SUMIFS(Coefficients!$D:$D,Coefficients!$A:$A,$B3,Coefficients!$B:$B,"内力"),1)*SUMIFS(TestCases!$D:$D,TestCases!$A:$A,$A3)+SUMIFS(StandardParams!$F:$F,StandardParams!$B:$B,"内力")*IFERROR(SUMIFS(Coefficients!$F:$F,Coefficients!$A:$A,$B3,Coefficients!$B:$B,"内力"),1)+SUMIFS(EquipPlans!$I:$I,EquipPlans!$A:$A,$C3,EquipPlans!$B:$B,"内力")+G3*10) | T3: =IF($A3="","",SUMIFS(StandardParams!$C:$C,StandardParams!$B:$B,"内力回复")*IFERROR(SUMIFS(Coefficients!$C:$C,Coefficients!$A:$A,$B3,Coefficients!$B:$B,"内力回复"),1)+SUMIFS(StandardParams!$D:$D,StandardParams!$B:$B,"内力回复")*IFERROR(SUMIFS(Coefficients!$D:$D,Coefficients!$A:$A,$B3,Coefficients!$B:$B,"内力回复"),1)*SUMIFS(TestCases!$D:$D,TestCases!$A:$A,$A3)+SUMIFS(StandardParams!$F:$F,StandardParams!$B:$B,"内力回复")*IFERROR(SUMIFS(Coefficients!$F:$F,Coefficients!$A:$A,$B3,Coefficients!$B:$B,"内力回复"),1)+SUMIFS(EquipPlans!$I:$I,EquipPlans!$A:$A,$C3,EquipPlans!$B:$B,"内力回复")+G3*0.5) | U3: =IF($A3="","",SUMIFS(StandardParams!$C:$C,StandardParams!$B:$B,"气血恢复")*IFERROR(SUMIFS(Coefficients!$C:$C,Coefficients!$A:$A,$B3,Coefficients!$B:$B,"气血恢复"),1)+SUMIFS(StandardParams!$D:$D,StandardParams!$B:$B,"气血恢复")*IFERROR(SUMIFS(Coefficients!$D:$D,Coefficients!$A:$A,$B3,Coefficients!$B:$B,"气血恢复"),1)*SUMIFS(TestCases!$D:$D,TestCases!$A:$A,$A3)+SUMIFS(StandardParams!$F:$F,StandardParams!$B:$B,"气血恢复")*IFERROR(SUMIFS(Coefficients!$F:$F,Coefficients!$A:$A,$B3,Coefficients!$B:$B,"气血恢复"),1)+SUMIFS(EquipPlans!$I:$I,EquipPlans!$A:$A,$C3,EquipPlans!$B:$B,"气血恢复")) | V3: =IF($A3="","",L3/(N3+L3+500)) | W3: =IF($A3="","",M3/(O3+M3+500)) | X3: =IF($A3="","",K3/(J3+K3))
A4: =IF(TestCases!A4="","",TestCases!A4) | B4: =IF($A4="","",TestCases!B4) | C4: =IF($A4="","",TestCases!C4) | D4: =IF($A4="","",SUMIFS(StandardParams!$C:$C,StandardParams!$B:$B,"臂力")*IFERROR(SUMIFS(Coefficients!$C:$C,Coefficients!$A:$A,$B4,Coefficients!$B:$B,"臂力"),1)+SUMIFS(StandardParams!$D:$D,StandardParams!$B:$B,"臂力")*IFERROR(SUMIFS(Coefficients!$D:$D,Coefficients!$A:$A,$B4,Coefficients!$B:$B,"臂力"),1)*SUMIFS(TestCases!$D:$D,TestCases!$A:$A,$A4)*SUMIFS(StandardParams!$E:$E,StandardParams!$B:$B,"臂力")*IFERROR(SUMIFS(Coefficients!$E:$E,Coefficients!$A:$A,$B4,Coefficients!$B:$B,"臂力"),1)+SUMIFS(StandardParams!$F:$F,StandardParams!$B:$B,"臂力")*IFERROR(SUMIFS(Coefficients!$F:$F,Coefficients!$A:$A,$B4,Coefficients!$B:$B,"臂力"),1)) | E4: =IF($A4="","",SUMIFS(StandardParams!$C:$C,StandardParams!$B:$B,"技巧")*IFERROR(SUMIFS(Coefficients!$C:$C,Coefficients!$A:$A,$B4,Coefficients!$B:$B,"技巧"),1)+SUMIFS(StandardParams!$D:$D,StandardParams!$B:$B,"技巧")*IFERROR(SUMIFS(Coefficients!$D:$D,Coefficients!$A:$A,$B4,Coefficients!$B:$B,"技巧"),1)*SUMIFS(TestCases!$D:$D,TestCases!$A:$A,$A4)*SUMIFS(StandardParams!$E:$E,StandardParams!$B:$B,"技巧")*IFERROR(SUMIFS(Coefficients!$E:$E,Coefficients!$A:$A,$B4,Coefficients!$B:$B,"技巧"),1)+SUMIFS(StandardParams!$F:$F,StandardParams!$B:$B,"技巧")*IFERROR(SUMIFS(Coefficients!$F:$F,Coefficients!$A:$A,$B4,Coefficients!$B:$B,"技巧"),1)) | F4: =IF($A4="","",SUMIFS(StandardParams!$C:$C,StandardParams!$B:$B,"根骨")*IFERROR(SUMIFS(Coefficients!$C:$C,Coefficients!$A:$A,$B4,Coefficients!$B:$B,"根骨"),1)+SUMIFS(StandardParams!$D:$D,StandardParams!$B:$B,"根骨")*IFERROR(SUMIFS(Coefficients!$D:$D,Coefficients!$A:$A,$B4,Coefficients!$B:$B,"根骨"),1)*SUMIFS(TestCases!$D:$D,TestCases!$A:$A,$A4)*SUMIFS(StandardParams!$E:$E,StandardParams!$B:$B,"根骨")*IFERROR(SUMIFS(Coefficients!$E:$E,Coefficients!$A:$A,$B4,Coefficients!$B:$B,"根骨"),1)+SUMIFS(StandardParams!$F:$F,StandardParams!$B:$B,"根骨")*IFERROR(SUMIFS(Coefficients!$F:$F,Coefficients!$A:$A,$B4,Coefficients!$B:$B,"根骨"),1)) | G4: =IF($A4="","",SUMIFS(StandardParams!$C:$C,StandardParams!$B:$B,"内息")*IFERROR(SUMIFS(Coefficients!$C:$C,Coefficients!$A:$A,$B4,Coefficients!$B:$B,"内息"),1)+SUMIFS(StandardParams!$D:$D,StandardParams!$B:$B,"内息")*IFERROR(SUMIFS(Coefficients!$D:$D,Coefficients!$A:$A,$B4,Coefficients!$B:$B,"内息"),1)*SUMIFS(TestCases!$D:$D,TestCases!$A:$A,$A4)*SUMIFS(StandardParams!$E:$E,StandardParams!$B:$B,"内息")*IFERROR(SUMIFS(Coefficients!$E:$E,Coefficients!$A:$A,$B4,Coefficients!$B:$B,"内息"),1)+SUMIFS(StandardParams!$F:$F,StandardParams!$B:$B,"内息")*IFERROR(SUMIFS(Coefficients!$F:$F,Coefficients!$A:$A,$B4,Coefficients!$B:$B,"内息"),1)) | H4: =IF($A4="","",SUMIFS(StandardParams!$C:$C,StandardParams!$B:$B,"身法")*IFERROR(SUMIFS(Coefficients!$C:$C,Coefficients!$A:$A,$B4,Coefficients!$B:$B,"身法"),1)+SUMIFS(StandardParams!$D:$D,StandardParams!$B:$B,"身法")*IFERROR(SUMIFS(Coefficients!$D:$D,Coefficients!$A:$A,$B4,Coefficients!$B:$B,"身法"),1)*SUMIFS(TestCases!$D:$D,TestCases!$A:$A,$A4)*SUMIFS(StandardParams!$E:$E,StandardParams!$B:$B,"身法")*IFERROR(SUMIFS(Coefficients!$E:$E,Coefficients!$A:$A,$B4,Coefficients!$B:$B,"身法"),1)+SUMIFS(StandardParams!$F:$F,StandardParams!$B:$B,"身法")*IFERROR(SUMIFS(Coefficients!$F:$F,Coefficients!$A:$A,$B4,Coefficients!$B:$B,"身法"),1)) | I4: =IF($A4="","",SUMIFS(StandardParams!$C:$C,StandardParams!$B:$B,"定力")*IFERROR(SUMIFS(Coefficients!$C:$C,Coefficients!$A:$A,$B4,Coefficients!$B:$B,"定力"),1)+SUMIFS(StandardParams!$D:$D,StandardParams!$B:$B,"定力")*IFERROR(SUMIFS(Coefficients!$D:$D,Coefficients!$A:$A,$B4,Coefficients!$B:$B,"定力"),1)*SUMIFS(TestCases!$D:$D,TestCases!$A:$A,$A4)*SUMIFS(StandardParams!$E:$E,StandardParams!$B:$B,"定力")*IFERROR(SUMIFS(Coefficients!$E:$E,Coefficients!$A:$A,$B4,Coefficients!$B:$B,"定力"),1)+SUMIFS(StandardParams!$F:$F,StandardParams!$B:$B,"定力")*IFERROR(SUMIFS(Coefficients!$F:$F,Coefficients!$A:$A,$B4,Coefficients!$B:$B,"定力"),1)) | J4: =IF($A4="","",SUMIFS(StandardParams!$C:$C,StandardParams!$B:$B,"攻击")*IFERROR(SUMIFS(Coefficients!$C:$C,Coefficients!$A:$A,$B4,Coefficients!$B:$B,"攻击"),1)+SUMIFS(StandardParams!$D:$D,StandardParams!$B:$B,"攻击")*IFERROR(SUMIFS(Coefficients!$D:$D,Coefficients!$A:$A,$B4,Coefficients!$B:$B,"攻击"),1)*SUMIFS(TestCases!$D:$D,TestCases!$A:$A,$A4)+SUMIFS(StandardParams!$F:$F,StandardParams!$B:$B,"攻击")*IFERROR(SUMIFS(Coefficients!$F:$F,Coefficients!$A:$A,$B4,Coefficients!$B:$B,"攻击"),1)+SUMIFS(EquipPlans!$I:$I,EquipPlans!$A:$A,$C4,EquipPlans!$B:$B,"攻击")+D4*4) | K4: =IF($A4="","",SUMIFS(StandardParams!$C:$C,StandardParams!$B:$B,"防御")*IFERROR(SUMIFS(Coefficients!$C:$C,Coefficients!$A:$A,$B4,Coefficients!$B:$B,"防御"),1)+SUMIFS(StandardParams!$D:$D,StandardParams!$B:$B,"防御")*IFERROR(SUMIFS(Coefficients!$D:$D,Coefficients!$A:$A,$B4,Coefficients!$B:$B,"防御"),1)*SUMIFS(TestCases!$D:$D,TestCases!$A:$A,$A4)+SUMIFS(StandardParams!$F:$F,StandardParams!$B:$B,"防御")*IFERROR(SUMIFS(Coefficients!$F:$F,Coefficients!$A:$A,$B4,Coefficients!$B:$B,"防御"),1)+SUMIFS(EquipPlans!$I:$I,EquipPlans!$A:$A,$C4,EquipPlans!$B:$B,"防御")) | L4: =IF($A4="","",SUMIFS(StandardParams!$C:$C,StandardParams!$B:$B,"速度")*IFERROR(SUMIFS(Coefficients!$C:$C,Coefficients!$A:$A,$B4,Coefficients!$B:$B,"速度"),1)+SUMIFS(StandardParams!$D:$D,StandardParams!$B:$B,"速度")*IFERROR(SUMIFS(Coefficients!$D:$D,Coefficients!$A:$A,$B4,Coefficients!$B:$B,"速度"),1)*SUMIFS(TestCases!$D:$D,TestCases!$A:$A,$A4)+SUMIFS(StandardParams!$F:$F,StandardParams!$B:$B,"速度")*IFERROR(SUMIFS(Coefficients!$F:$F,Coefficients!$A:$A,$B4,Coefficients!$B:$B,"速度"),1)+SUMIFS(EquipPlans!$I:$I,EquipPlans!$A:$A,$C4,EquipPlans!$B:$B,"速度")+H4*2) | M4: =IF($A4="","",SUMIFS(StandardParams!$C:$C,StandardParams!$B:$B,"命中")*IFERROR(SUMIFS(Coefficients!$C:$C,Coefficients!$A:$A,$B4,Coefficients!$B:$B,"命中"),1)+SUMIFS(StandardParams!$D:$D,StandardParams!$B:$B,"命中")*IFERROR(SUMIFS(Coefficients!$D:$D,Coefficients!$A:$A,$B4,Coefficients!$B:$B,"命中"),1)*SUMIFS(TestCases!$D:$D,TestCases!$A:$A,$A4)+SUMIFS(StandardParams!$F:$F,StandardParams!$B:$B,"命中")*IFERROR(SUMIFS(Coefficients!$F:$F,Coefficients!$A:$A,$B4,Coefficients!$B:$B,"命中"),1)+SUMIFS(EquipPlans!$I:$I,EquipPlans!$A:$A,$C4,EquipPlans!$B:$B,"命中")+E4*2) | N4: =IF($A4="","",SUMIFS(StandardParams!$C:$C,StandardParams!$B:$B,"招架")*IFERROR(SUMIFS(Coefficients!$C:$C,Coefficients!$A:$A,$B4,Coefficients!$B:$B,"招架"),1)+SUMIFS(StandardParams!$D:$D,StandardParams!$B:$B,"招架")*IFERROR(SUMIFS(Coefficients!$D:$D,Coefficients!$A:$A,$B4,Coefficients!$B:$B,"招架"),1)*SUMIFS(TestCases!$D:$D,TestCases!$A:$A,$A4)+SUMIFS(StandardParams!$F:$F,StandardParams!$B:$B,"招架")*IFERROR(SUMIFS(Coefficients!$F:$F,Coefficients!$A:$A,$B4,Coefficients!$B:$B,"招架"),1)+SUMIFS(EquipPlans!$I:$I,EquipPlans!$A:$A,$C4,EquipPlans!$B:$B,"招架")+E4*2) | O4: =IF($A4="","",SUMIFS(StandardParams!$C:$C,StandardParams!$B:$B,"偏斜")*IFERROR(SUMIFS(Coefficients!$C:$C,Coefficients!$A:$A,$B4,Coefficients!$B:$B,"偏斜"),1)+SUMIFS(StandardParams!$D:$D,StandardParams!$B:$B,"偏斜")*IFERROR(SUMIFS(Coefficients!$D:$D,Coefficients!$A:$A,$B4,Coefficients!$B:$B,"偏斜"),1)*SUMIFS(TestCases!$D:$D,TestCases!$A:$A,$A4)+SUMIFS(StandardParams!$F:$F,StandardParams!$B:$B,"偏斜")*IFERROR(SUMIFS(Coefficients!$F:$F,Coefficients!$A:$A,$B4,Coefficients!$B:$B,"偏斜"),1)+SUMIFS(EquipPlans!$I:$I,EquipPlans!$A:$A,$C4,EquipPlans!$B:$B,"偏斜")+H4*2) | P4: =IF($A4="","",SUMIFS(StandardParams!$C:$C,StandardParams!$B:$B,"抵抗")*IFERROR(SUMIFS(Coefficients!$C:$C,Coefficients!$A:$A,$B4,Coefficients!$B:$B,"抵抗"),1)+SUMIFS(StandardParams!$D:$D,StandardParams!$B:$B,"抵抗")*IFERROR(SUMIFS(Coefficients!$D:$D,Coefficients!$A:$A,$B4,Coefficients!$B:$B,"抵抗"),1)*SUMIFS(TestCases!$D:$D,TestCases!$A:$A,$A4)+SUMIFS(StandardParams!$F:$F,StandardParams!$B:$B,"抵抗")*IFERROR(SUMIFS(Coefficients!$F:$F,Coefficients!$A:$A,$B4,Coefficients!$B:$B,"抵抗"),1)+SUMIFS(EquipPlans!$I:$I,EquipPlans!$A:$A,$C4,EquipPlans!$B:$B,"抵抗")+I4*2.5) | Q4: =IF($A4="","",SUMIFS(StandardParams!$C:$C,StandardParams!$B:$B,"韧性")*IFERROR(SUMIFS(Coefficients!$C:$C,Coefficients!$A:$A,$B4,Coefficients!$B:$B,"韧性"),1)+SUMIFS(StandardParams!$D:$D,StandardParams!$B:$B,"韧性")*IFERROR(SUMIFS(Coefficients!$D:$D,Coefficients!$A:$A,$B4,Coefficients!$B:$B,"韧性"),1)*SUMIFS(TestCases!$D:$D,TestCases!$A:$A,$A4)+SUMIFS(StandardParams!$F:$F,StandardParams!$B:$B,"韧性")*IFERROR(SUMIFS(Coefficients!$F:$F,Coefficients!$A:$A,$B4,Coefficients!$B:$B,"韧性"),1)+SUMIFS(EquipPlans!$I:$I,EquipPlans!$A:$A,$C4,EquipPlans!$B:$B,"韧性")+F4) | R4: =IF($A4="","",SUMIFS(StandardParams!$C:$C,StandardParams!$B:$B,"气血")*IFERROR(SUMIFS(Coefficients!$C:$C,Coefficients!$A:$A,$B4,Coefficients!$B:$B,"气血"),1)+SUMIFS(StandardParams!$D:$D,StandardParams!$B:$B,"气血")*IFERROR(SUMIFS(Coefficients!$D:$D,Coefficients!$A:$A,$B4,Coefficients!$B:$B,"气血"),1)*SUMIFS(TestCases!$D:$D,TestCases!$A:$A,$A4)+SUMIFS(StandardParams!$F:$F,StandardParams!$B:$B,"气血")*IFERROR(SUMIFS(Coefficients!$F:$F,Coefficients!$A:$A,$B4,Coefficients!$B:$B,"气血"),1)+SUMIFS(EquipPlans!$I:$I,EquipPlans!$A:$A,$C4,EquipPlans!$B:$B,"气血")+F4*20) | S4: =IF($A4="","",SUMIFS(StandardParams!$C:$C,StandardParams!$B:$B,"内力")*IFERROR(SUMIFS(Coefficients!$C:$C,Coefficients!$A:$A,$B4,Coefficients!$B:$B,"内力"),1)+SUMIFS(StandardParams!$D:$D,StandardParams!$B:$B,"内力")*IFERROR(SUMIFS(Coefficients!$D:$D,Coefficients!$A:$A,$B4,Coefficients!$B:$B,"内力"),1)*SUMIFS(TestCases!$D:$D,TestCases!$A:$A,$A4)+SUMIFS(StandardParams!$F:$F,StandardParams!$B:$B,"内力")*IFERROR(SUMIFS(Coefficients!$F:$F,Coefficients!$A:$A,$B4,Coefficients!$B:$B,"内力"),1)+SUMIFS(EquipPlans!$I:$I,EquipPlans!$A:$A,$C4,EquipPlans!$B:$B,"内力")+G4*10) | T4: =IF($A4="","",SUMIFS(StandardParams!$C:$C,StandardParams!$B:$B,"内力回复")*IFERROR(SUMIFS(Coefficients!$C:$C,Coefficients!$A:$A,$B4,Coefficients!$B:$B,"内力回复"),1)+SUMIFS(StandardParams!$D:$D,StandardParams!$B:$B,"内力回复")*IFERROR(SUMIFS(Coefficients!$D:$D,Coefficients!$A:$A,$B4,Coefficients!$B:$B,"内力回复"),1)*SUMIFS(TestCases!$D:$D,TestCases!$A:$A,$A4)+SUMIFS(StandardParams!$F:$F,StandardParams!$B:$B,"内力回复")*IFERROR(SUMIFS(Coefficients!$F:$F,Coefficients!$A:$A,$B4,Coefficients!$B:$B,"内力回复"),1)+SUMIFS(EquipPlans!$I:$I,EquipPlans!$A:$A,$C4,EquipPlans!$B:$B,"内力回复")+G4*0.5) | U4: =IF($A4="","",SUMIFS(StandardParams!$C:$C,StandardParams!$B:$B,"气血恢复")*IFERROR(SUMIFS(Coefficients!$C:$C,Coefficients!$A:$A,$B4,Coefficients!$B:$B,"气血恢复"),1)+SUMIFS(StandardParams!$D:$D,StandardParams!$B:$B,"气血恢复")*IFERROR(SUMIFS(Coefficients!$D:$D,Coefficients!$A:$A,$B4,Coefficients!$B:$B,"气血恢复"),1)*SUMIFS(TestCases!$D:$D,TestCases!$A:$A,$A4)+SUMIFS(StandardParams!$F:$F,StandardParams!$B:$B,"气血恢复")*IFERROR(SUMIFS(Coefficients!$F:$F,Coefficients!$A:$A,$B4,Coefficients!$B:$B,"气血恢复"),1)+SUMIFS(EquipPlans!$I:$I,EquipPlans!$A:$A,$C4,EquipPlans!$B:$B,"气血恢复")) | V4: =IF($A4="","",L4/(N4+L4+500)) | W4: =IF($A4="","",M4/(O4+M4+500)) | X4: =IF($A4="","",K4/(J4+K4))
A5: =IF(TestCases!A5="","",TestCases!A5) | B5: =IF($A5="","",TestCases!B5) | C5: =IF($A5="","",TestCases!C5) | D5: =IF($A5="","",SUMIFS(StandardParams!$C:$C,StandardParams!$B:$B,"臂力")*IFERROR(SUMIFS(Coefficients!$C:$C,Coefficients!$A:$A,$B5,Coefficients!$B:$B,"臂力"),1)+SUMIFS(StandardParams!$D:$D,StandardParams!$B:$B,"臂力")*IFERROR(SUMIFS(Coefficients!$D:$D,Coefficients!$A:$A,$B5,Coefficients!$B:$B,"臂力"),1)*SUMIFS(TestCases!$D:$D,TestCases!$A:$A,$A5)*SUMIFS(StandardParams!$E:$E,StandardParams!$B:$B,"臂力")*IFERROR(SUMIFS(Coefficients!$E:$E,Coefficients!$A:$A,$B5,Coefficients!$B:$B,"臂力"),1)+SUMIFS(StandardParams!$F:$F,StandardParams!$B:$B,"臂力")*IFERROR(SUMIFS(Coefficients!$F:$F,Coefficients!$A:$A,$B5,Coefficients!$B:$B,"臂力"),1)) | E5: =IF($A5="","",SUMIFS(StandardParams!$C:$C,StandardParams!$B:$B,"技巧")*IFERROR(SUMIFS(Coefficients!$C:$C,Coefficients!$A:$A,$B5,Coefficients!$B:$B,"技巧"),1)+SUMIFS(StandardParams!$D:$D,StandardParams!$B:$B,"技巧")*IFERROR(SUMIFS(Coefficients!$D:$D,Coefficients!$A:$A,$B5,Coefficients!$B:$B,"技巧"),1)*SUMIFS(TestCases!$D:$D,TestCases!$A:$A,$A5)*SUMIFS(StandardParams!$E:$E,StandardParams!$B:$B,"技巧")*IFERROR(SUMIFS(Coefficients!$E:$E,Coefficients!$A:$A,$B5,Coefficients!$B:$B,"技巧"),1)+SUMIFS(StandardParams!$F:$F,StandardParams!$B:$B,"技巧")*IFERROR(SUMIFS(Coefficients!$F:$F,Coefficients!$A:$A,$B5,Coefficients!$B:$B,"技巧"),1)) | F5: =IF($A5="","",SUMIFS(StandardParams!$C:$C,StandardParams!$B:$B,"根骨")*IFERROR(SUMIFS(Coefficients!$C:$C,Coefficients!$A:$A,$B5,Coefficients!$B:$B,"根骨"),1)+SUMIFS(StandardParams!$D:$D,StandardParams!$B:$B,"根骨")*IFERROR(SUMIFS(Coefficients!$D:$D,Coefficients!$A:$A,$B5,Coefficients!$B:$B,"根骨"),1)*SUMIFS(TestCases!$D:$D,TestCases!$A:$A,$A5)*SUMIFS(StandardParams!$E:$E,StandardParams!$B:$B,"根骨")*IFERROR(SUMIFS(Coefficients!$E:$E,Coefficients!$A:$A,$B5,Coefficients!$B:$B,"根骨"),1)+SUMIFS(StandardParams!$F:$F,StandardParams!$B:$B,"根骨")*IFERROR(SUMIFS(Coefficients!$F:$F,Coefficients!$A:$A,$B5,Coefficients!$B:$B,"根骨"),1)) | G5: =IF($A5="","",SUMIFS(StandardParams!$C:$C,StandardParams!$B:$B,"内息")*IFERROR(SUMIFS(Coefficients!$C:$C,Coefficients!$A:$A,$B5,Coefficients!$B:$B,"内息"),1)+SUMIFS(StandardParams!$D:$D,StandardParams!$B:$B,"内息")*IFERROR(SUMIFS(Coefficients!$D:$D,Coefficients!$A:$A,$B5,Coefficients!$B:$B,"内息"),1)*SUMIFS(TestCases!$D:$D,TestCases!$A:$A,$A5)*SUMIFS(StandardParams!$E:$E,StandardParams!$B:$B,"内息")*IFERROR(SUMIFS(Coefficients!$E:$E,Coefficients!$A:$A,$B5,Coefficients!$B:$B,"内息"),1)+SUMIFS(StandardParams!$F:$F,StandardParams!$B:$B,"内息")*IFERROR(SUMIFS(Coefficients!$F:$F,Coefficients!$A:$A,$B5,Coefficients!$B:$B,"内息"),1)) | H5: =IF($A5="","",SUMIFS(StandardParams!$C:$C,StandardParams!$B:$B,"身法")*IFERROR(SUMIFS(Coefficients!$C:$C,Coefficients!$A:$A,$B5,Coefficients!$B:$B,"身法"),1)+SUMIFS(StandardParams!$D:$D,StandardParams!$B:$B,"身法")*IFERROR(SUMIFS(Coefficients!$D:$D,Coefficients!$A:$A,$B5,Coefficients!$B:$B,"身法"),1)*SUMIFS(TestCases!$D:$D,TestCases!$A:$A,$A5)*SUMIFS(StandardParams!$E:$E,StandardParams!$B:$B,"身法")*IFERROR(SUMIFS(Coefficients!$E:$E,Coefficients!$A:$A,$B5,Coefficients!$B:$B,"身法"),1)+SUMIFS(StandardParams!$F:$F,StandardParams!$B:$B,"身法")*IFERROR(SUMIFS(Coefficients!$F:$F,Coefficients!$A:$A,$B5,Coefficients!$B:$B,"身法"),1)) | I5: =IF($A5="","",SUMIFS(StandardParams!$C:$C,StandardParams!$B:$B,"定力")*IFERROR(SUMIFS(Coefficients!$C:$C,Coefficients!$A:$A,$B5,Coefficients!$B:$B,"定力"),1)+SUMIFS(StandardParams!$D:$D,StandardParams!$B:$B,"定力")*IFERROR(SUMIFS(Coefficients!$D:$D,Coefficients!$A:$A,$B5,Coefficients!$B:$B,"定力"),1)*SUMIFS(TestCases!$D:$D,TestCases!$A:$A,$A5)*SUMIFS(StandardParams!$E:$E,StandardParams!$B:$B,"定力")*IFERROR(SUMIFS(Coefficients!$E:$E,Coefficients!$A:$A,$B5,Coefficients!$B:$B,"定力"),1)+SUMIFS(StandardParams!$F:$F,StandardParams!$B:$B,"定力")*IFERROR(SUMIFS(Coefficients!$F:$F,Coefficients!$A:$A,$B5,Coefficients!$B:$B,"定力"),1)) | J5: =IF($A5="","",SUMIFS(StandardParams!$C:$C,StandardParams!$B:$B,"攻击")*IFERROR(SUMIFS(Coefficients!$C:$C,Coefficients!$A:$A,$B5,Coefficients!$B:$B,"攻击"),1)+SUMIFS(StandardParams!$D:$D,StandardParams!$B:$B,"攻击")*IFERROR(SUMIFS(Coefficients!$D:$D,Coefficients!$A:$A,$B5,Coefficients!$B:$B,"攻击"),1)*SUMIFS(TestCases!$D:$D,TestCases!$A:$A,$A5)+SUMIFS(StandardParams!$F:$F,StandardParams!$B:$B,"攻击")*IFERROR(SUMIFS(Coefficients!$F:$F,Coefficients!$A:$A,$B5,Coefficients!$B:$B,"攻击"),1)+SUMIFS(EquipPlans!$I:$I,EquipPlans!$A:$A,$C5,EquipPlans!$B:$B,"攻击")+D5*4) | K5: =IF($A5="","",SUMIFS(StandardParams!$C:$C,StandardParams!$B:$B,"防御")*IFERROR(SUMIFS(Coefficients!$C:$C,Coefficients!$A:$A,$B5,Coefficients!$B:$B,"防御"),1)+SUMIFS(StandardParams!$D:$D,StandardParams!$B:$B,"防御")*IFERROR(SUMIFS(Coefficients!$D:$D,Coefficients!$A:$A,$B5,Coefficients!$B:$B,"防御"),1)*SUMIFS(TestCases!$D:$D,TestCases!$A:$A,$A5)+SUMIFS(StandardParams!$F:$F,StandardParams!$B:$B,"防御")*IFERROR(SUMIFS(Coefficients!$F:$F,Coefficients!$A:$A,$B5,Coefficients!$B:$B,"防御"),1)+SUMIFS(EquipPlans!$I:$I,EquipPlans!$A:$A,$C5,EquipPlans!$B:$B,"防御")) | L5: =IF($A5="","",SUMIFS(StandardParams!$C:$C,StandardParams!$B:$B,"速度")*IFERROR(SUMIFS(Coefficients!$C:$C,Coefficients!$A:$A,$B5,Coefficients!$B:$B,"速度"),1)+SUMIFS(StandardParams!$D:$D,StandardParams!$B:$B,"速度")*IFERROR(SUMIFS(Coefficients!$D:$D,Coefficients!$A:$A,$B5,Coefficients!$B:$B,"速度"),1)*SUMIFS(TestCases!$D:$D,TestCases!$A:$A,$A5)+SUMIFS(StandardParams!$F:$F,StandardParams!$B:$B,"速度")*IFERROR(SUMIFS(Coefficients!$F:$F,Coefficients!$A:$A,$B5,Coefficients!$B:$B,"速度"),1)+SUMIFS(EquipPlans!$I:$I,EquipPlans!$A:$A,$C5,EquipPlans!$B:$B,"速度")+H5*2) | M5: =IF($A5="","",SUMIFS(StandardParams!$C:$C,StandardParams!$B:$B,"命中")*IFERROR(SUMIFS(Coefficients!$C:$C,Coefficients!$A:$A,$B5,Coefficients!$B:$B,"命中"),1)+SUMIFS(StandardParams!$D:$D,StandardParams!$B:$B,"命中")*IFERROR(SUMIFS(Coefficients!$D:$D,Coefficients!$A:$A,$B5,Coefficients!$B:$B,"命中"),1)*SUMIFS(TestCases!$D:$D,TestCases!$A:$A,$A5)+SUMIFS(StandardParams!$F:$F,StandardParams!$B:$B,"命中")*IFERROR(SUMIFS(Coefficients!$F:$F,Coefficients!$A:$A,$B5,Coefficients!$B:$B,"命中"),1)+SUMIFS(EquipPlans!$I:$I,EquipPlans!$A:$A,$C5,EquipPlans!$B:$B,"命中")+E5*2) | N5: =IF($A5="","",SUMIFS(StandardParams!$C:$C,StandardParams!$B:$B,"招架")*IFERROR(SUMIFS(Coefficients!$C:$C,Coefficients!$A:$A,$B5,Coefficients!$B:$B,"招架"),1)+SUMIFS(StandardParams!$D:$D,StandardParams!$B:$B,"招架")*IFERROR(SUMIFS(Coefficients!$D:$D,Coefficients!$A:$A,$B5,Coefficients!$B:$B,"招架"),1)*SUMIFS(TestCases!$D:$D,TestCases!$A:$A,$A5)+SUMIFS(StandardParams!$F:$F,StandardParams!$B:$B,"招架")*IFERROR(SUMIFS(Coefficients!$F:$F,Coefficients!$A:$A,$B5,Coefficients!$B:$B,"招架"),1)+SUMIFS(EquipPlans!$I:$I,EquipPlans!$A:$A,$C5,EquipPlans!$B:$B,"招架")+E5*2) | O5: =IF($A5="","",SUMIFS(StandardParams!$C:$C,StandardParams!$B:$B,"偏斜")*IFERROR(SUMIFS(Coefficients!$C:$C,Coefficients!$A:$A,$B5,Coefficients!$B:$B,"偏斜"),1)+SUMIFS(StandardParams!$D:$D,StandardParams!$B:$B,"偏斜")*IFERROR(SUMIFS(Coefficients!$D:$D,Coefficients!$A:$A,$B5,Coefficients!$B:$B,"偏斜"),1)*SUMIFS(TestCases!$D:$D,TestCases!$A:$A,$A5)+SUMIFS(StandardParams!$F:$F,StandardParams!$B:$B,"偏斜")*IFERROR(SUMIFS(Coefficients!$F:$F,Coefficients!$A:$A,$B5,Coefficients!$B:$B,"偏斜"),1)+SUMIFS(EquipPlans!$I:$I,EquipPlans!$A:$A,$C5,EquipPlans!$B:$B,"偏斜")+H5*2) | P5: =IF($A5="","",SUMIFS(StandardParams!$C:$C,StandardParams!$B:$B,"抵抗")*IFERROR(SUMIFS(Coefficients!$C:$C,Coefficients!$A:$A,$B5,Coefficients!$B:$B,"抵抗"),1)+SUMIFS(StandardParams!$D:$D,StandardParams!$B:$B,"抵抗")*IFERROR(SUMIFS(Coefficients!$D:$D,Coefficients!$A:$A,$B5,Coefficients!$B:$B,"抵抗"),1)*SUMIFS(TestCases!$D:$D,TestCases!$A:$A,$A5)+SUMIFS(StandardParams!$F:$F,StandardParams!$B:$B,"抵抗")*IFERROR(SUMIFS(Coefficients!$F:$F,Coefficients!$A:$A,$B5,Coefficients!$B:$B,"抵抗"),1)+SUMIFS(EquipPlans!$I:$I,EquipPlans!$A:$A,$C5,EquipPlans!$B:$B,"抵抗")+I5*2.5) | Q5: =IF($A5="","",SUMIFS(StandardParams!$C:$C,StandardParams!$B:$B,"韧性")*IFERROR(SUMIFS(Coefficients!$C:$C,Coefficients!$A:$A,$B5,Coefficients!$B:$B,"韧性"),1)+SUMIFS(StandardParams!$D:$D,StandardParams!$B:$B,"韧性")*IFERROR(SUMIFS(Coefficients!$D:$D,Coefficients!$A:$A,$B5,Coefficients!$B:$B,"韧性"),1)*SUMIFS(TestCases!$D:$D,TestCases!$A:$A,$A5)+SUMIFS(StandardParams!$F:$F,StandardParams!$B:$B,"韧性")*IFERROR(SUMIFS(Coefficients!$F:$F,Coefficients!$A:$A,$B5,Coefficients!$B:$B,"韧性"),1)+SUMIFS(EquipPlans!$I:$I,EquipPlans!$A:$A,$C5,EquipPlans!$B:$B,"韧性")+F5) | R5: =IF($A5="","",SUMIFS(StandardParams!$C:$C,StandardParams!$B:$B,"气血")*IFERROR(SUMIFS(Coefficients!$C:$C,Coefficients!$A:$A,$B5,Coefficients!$B:$B,"气血"),1)+SUMIFS(StandardParams!$D:$D,StandardParams!$B:$B,"气血")*IFERROR(SUMIFS(Coefficients!$D:$D,Coefficients!$A:$A,$B5,Coefficients!$B:$B,"气血"),1)*SUMIFS(TestCases!$D:$D,TestCases!$A:$A,$A5)+SUMIFS(StandardParams!$F:$F,StandardParams!$B:$B,"气血")*IFERROR(SUMIFS(Coefficients!$F:$F,Coefficients!$A:$A,$B5,Coefficients!$B:$B,"气血"),1)+SUMIFS(EquipPlans!$I:$I,EquipPlans!$A:$A,$C5,EquipPlans!$B:$B,"气血")+F5*20) | S5: =IF($A5="","",SUMIFS(StandardParams!$C:$C,StandardParams!$B:$B,"内力")*IFERROR(SUMIFS(Coefficients!$C:$C,Coefficients!$A:$A,$B5,Coefficients!$B:$B,"内力"),1)+SUMIFS(StandardParams!$D:$D,StandardParams!$B:$B,"内力")*IFERROR(SUMIFS(Coefficients!$D:$D,Coefficients!$A:$A,$B5,Coefficients!$B:$B,"内力"),1)*SUMIFS(TestCases!$D:$D,TestCases!$A:$A,$A5)+SUMIFS(StandardParams!$F:$F,StandardParams!$B:$B,"内力")*IFERROR(SUMIFS(Coefficients!$F:$F,Coefficients!$A:$A,$B5,Coefficients!$B:$B,"内力"),1)+SUMIFS(EquipPlans!$I:$I,EquipPlans!$A:$A,$C5,EquipPlans!$B:$B,"内力")+G5*10) | T5: =IF($A5="","",SUMIFS(StandardParams!$C:$C,StandardParams!$B:$B,"内力回复")*IFERROR(SUMIFS(Coefficients!$C:$C,Coefficients!$A:$A,$B5,Coefficients!$B:$B,"内力回复"),1)+SUMIFS(StandardParams!$D:$D,StandardParams!$B:$B,"内力回复")*IFERROR(SUMIFS(Coefficients!$D:$D,Coefficients!$A:$A,$B5,Coefficients!$B:$B,"内力回复"),1)*SUMIFS(TestCases!$D:$D,TestCases!$A:$A,$A5)+SUMIFS(StandardParams!$F:$F,StandardParams!$B:$B,"内力回复")*IFERROR(SUMIFS(Coefficients!$F:$F,Coefficients!$A:$A,$B5,Coefficients!$B:$B,"内力回复"),1)+SUMIFS(EquipPlans!$I:$I,EquipPlans!$A:$A,$C5,EquipPlans!$B:$B,"内力回复")+G5*0.5) | U5: =IF($A5="","",SUMIFS(StandardParams!$C:$C,StandardParams!$B:$B,"气血恢复")*IFERROR(SUMIFS(Coefficients!$C:$C,Coefficients!$A:$A,$B5,Coefficients!$B:$B,"气血恢复"),1)+SUMIFS(StandardParams!$D:$D,StandardParams!$B:$B,"气血恢复")*IFERROR(SUMIFS(Coefficients!$D:$D,Coefficients!$A:$A,$B5,Coefficients!$B:$B,"气血恢复"),1)*SUMIFS(TestCases!$D:$D,TestCases!$A:$A,$A5)+SUMIFS(StandardParams!$F:$F,StandardParams!$B:$B,"气血恢复")*IFERROR(SUMIFS(Coefficients!$F:$F,Coefficients!$A:$A,$B5,Coefficients!$B:$B,"气血恢复"),1)+SUMIFS(EquipPlans!$I:$I,EquipPlans!$A:$A,$C5,EquipPlans!$B:$B,"气血恢复")) | V5: =IF($A5="","",L5/(N5+L5+500)) | W5: =IF($A5="","",M5/(O5+M5+500)) | X5: =IF($A5="","",K5/(J5+K5))
A6: =IF(TestCases!A6="","",TestCases!A6) | B6: =IF($A6="","",TestCases!B6) | C6: =IF($A6="","",TestCases!C6) | D6: =IF($A6="","",SUMIFS(StandardParams!$C:$C,StandardParams!$B:$B,"臂力")*IFERROR(SUMIFS(Coefficients!$C:$C,Coefficients!$A:$A,$B6,Coefficients!$B:$B,"臂力"),1)+SUMIFS(StandardParams!$D:$D,StandardParams!$B:$B,"臂力")*IFERROR(SUMIFS(Coefficients!$D:$D,Coefficients!$A:$A,$B6,Coefficients!$B:$B,"臂力"),1)*SUMIFS(TestCases!$D:$D,TestCases!$A:$A,$A6)*SUMIFS(StandardParams!$E:$E,StandardParams!$B:$B,"臂力")*IFERROR(SUMIFS(Coefficients!$E:$E,Coefficients!$A:$A,$B6,Coefficients!$B:$B,"臂力"),1)+SUMIFS(StandardParams!$F:$F,StandardParams!$B:$B,"臂力")*IFERROR(SUMIFS(Coefficients!$F:$F,Coefficients!$A:$A,$B6,Coefficients!$B:$B,"臂力"),1)) | E6: =IF($A6="","",SUMIFS(StandardParams!$C:$C,StandardParams!$B:$B,"技巧")*IFERROR(SUMIFS(Coefficients!$C:$C,Coefficients!$A:$A,$B6,Coefficients!$B:$B,"技巧"),1)+SUMIFS(StandardParams!$D:$D,StandardParams!$B:$B,"技巧")*IFERROR(SUMIFS(Coefficients!$D:$D,Coefficients!$A:$A,$B6,Coefficients!$B:$B,"技巧"),1)*SUMIFS(TestCases!$D:$D,TestCases!$A:$A,$A6)*SUMIFS(StandardParams!$E:$E,StandardParams!$B:$B,"技巧")*IFERROR(SUMIFS(Coefficients!$E:$E,Coefficients!$A:$A,$B6,Coefficients!$B:$B,"技巧"),1)+SUMIFS(StandardParams!$F:$F,StandardParams!$B:$B,"技巧")*IFERROR(SUMIFS(Coefficients!$F:$F,Coefficients!$A:$A,$B6,Coefficients!$B:$B,"技巧"),1)) | F6: =IF($A6="","",SUMIFS(StandardParams!$C:$C,StandardParams!$B:$B,"根骨")*IFERROR(SUMIFS(Coefficients!$C:$C,Coefficients!$A:$A,$B6,Coefficients!$B:$B,"根骨"),1)+SUMIFS(StandardParams!$D:$D,StandardParams!$B:$B,"根骨")*IFERROR(SUMIFS(Coefficients!$D:$D,Coefficients!$A:$A,$B6,Coefficients!$B:$B,"根骨"),1)*SUMIFS(TestCases!$D:$D,TestCases!$A:$A,$A6)*SUMIFS(StandardParams!$E:$E,StandardParams!$B:$B,"根骨")*IFERROR(SUMIFS(Coefficients!$E:$E,Coefficients!$A:$A,$B6,Coefficients!$B:$B,"根骨"),1)+SUMIFS(StandardParams!$F:$F,StandardParams!$B:$B,"根骨")*IFERROR(SUMIFS(Coefficients!$F:$F,Coefficients!$A:$A,$B6,Coefficients!$B:$B,"根骨"),1)) | G6: =IF($A6="","",SUMIFS(StandardParams!$C:$C,StandardParams!$B:$B,"内息")*IFERROR(SUMIFS(Coefficients!$C:$C,Coefficients!$A:$A,$B6,Coefficients!$B:$B,"内息"),1)+SUMIFS(StandardParams!$D:$D,StandardParams!$B:$B,"内息")*IFERROR(SUMIFS(Coefficients!$D:$D,Coefficients!$A:$A,$B6,Coefficients!$B:$B,"内息"),1)*SUMIFS(TestCases!$D:$D,TestCases!$A:$A,$A6)*SUMIFS(StandardParams!$E:$E,StandardParams!$B:$B,"内息")*IFERROR(SUMIFS(Coefficients!$E:$E,Coefficients!$A:$A,$B6,Coefficients!$B:$B,"内息"),1)+SUMIFS(StandardParams!$F:$F,StandardParams!$B:$B,"内息")*IFERROR(SUMIFS(Coefficients!$F:$F,Coefficients!$A:$A,$B6,Coefficients!$B:$B,"内息"),1)) | H6: =IF($A6="","",SUMIFS(StandardParams!$C:$C,StandardParams!$B:$B,"身法")*IFERROR(SUMIFS(Coefficients!$C:$C,Coefficients!$A:$A,$B6,Coefficients!$B:$B,"身法"),1)+SUMIFS(StandardParams!$D:$D,StandardParams!$B:$B,"身法")*IFERROR(SUMIFS(Coefficients!$D:$D,Coefficients!$A:$A,$B6,Coefficients!$B:$B,"身法"),1)*SUMIFS(TestCases!$D:$D,TestCases!$A:$A,$A6)*SUMIFS(StandardParams!$E:$E,StandardParams!$B:$B,"身法")*IFERROR(SUMIFS(Coefficients!$E:$E,Coefficients!$A:$A,$B6,Coefficients!$B:$B,"身法"),1)+SUMIFS(StandardParams!$F:$F,StandardParams!$B:$B,"身法")*IFERROR(SUMIFS(Coefficients!$F:$F,Coefficients!$A:$A,$B6,Coefficients!$B:$B,"身法"),1)) | I6: =IF($A6="","",SUMIFS(StandardParams!$C:$C,StandardParams!$B:$B,"定力")*IFERROR(SUMIFS(Coefficients!$C:$C,Coefficients!$A:$A,$B6,Coefficients!$B:$B,"定力"),1)+SUMIFS(StandardParams!$D:$D,StandardParams!$B:$B,"定力")*IFERROR(SUMIFS(Coefficients!$D:$D,Coefficients!$A:$A,$B6,Coefficients!$B:$B,"定力"),1)*SUMIFS(TestCases!$D:$D,TestCases!$A:$A,$A6)*SUMIFS(StandardParams!$E:$E,StandardParams!$B:$B,"定力")*IFERROR(SUMIFS(Coefficients!$E:$E,Coefficients!$A:$A,$B6,Coefficients!$B:$B,"定力"),1)+SUMIFS(StandardParams!$F:$F,StandardParams!$B:$B,"定力")*IFERROR(SUMIFS(Coefficients!$F:$F,Coefficients!$A:$A,$B6,Coefficients!$B:$B,"定力"),1)) | J6: =IF($A6="","",SUMIFS(StandardParams!$C:$C,StandardParams!$B:$B,"攻击")*IFERROR(SUMIFS(Coefficients!$C:$C,Coefficients!$A:$A,$B6,Coefficients!$B:$B,"攻击"),1)+SUMIFS(StandardParams!$D:$D,StandardParams!$B:$B,"攻击")*IFERROR(SUMIFS(Coefficients!$D:$D,Coefficients!$A:$A,$B6,Coefficients!$B:$B,"攻击"),1)*SUMIFS(TestCases!$D:$D,TestCases!$A:$A,$A6)+SUMIFS(StandardParams!$F:$F,StandardParams!$B:$B,"攻击")*IFERROR(SUMIFS(Coefficients!$F:$F,Coefficients!$A:$A,$B6,Coefficients!$B:$B,"攻击"),1)+SUMIFS(EquipPlans!$I:$I,EquipPlans!$A:$A,$C6,EquipPlans!$B:$B,"攻击")+D6*4) | K6: =IF($A6="","",SUMIFS(StandardParams!$C:$C,StandardParams!$B:$B,"防御")*IFERROR(SUMIFS(Coefficients!$C:$C,Coefficients!$A:$A,$B6,Coefficients!$B:$B,"防御"),1)+SUMIFS(StandardParams!$D:$D,StandardParams!$B:$B,"防御")*IFERROR(SUMIFS(Coefficients!$D:$D,Coefficients!$A:$A,$B6,Coefficients!$B:$B,"防御"),1)*SUMIFS(TestCases!$D:$D,TestCases!$A:$A,$A6)+SUMIFS(StandardParams!$F:$F,StandardParams!$B:$B,"防御")*IFERROR(SUMIFS(Coefficients!$F:$F,Coefficients!$A:$A,$B6,Coefficients!$B:$B,"防御"),1)+SUMIFS(EquipPlans!$I:$I,EquipPlans!$A:$A,$C6,EquipPlans!$B:$B,"防御")) | L6: =IF($A6="","",SUMIFS(StandardParams!$C:$C,StandardParams!$B:$B,"速度")*IFERROR(SUMIFS(Coefficients!$C:$C,Coefficients!$A:$A,$B6,Coefficients!$B:$B,"速度"),1)+SUMIFS(StandardParams!$D:$D,StandardParams!$B:$B,"速度")*IFERROR(SUMIFS(Coefficients!$D:$D,Coefficients!$A:$A,$B6,Coefficients!$B:$B,"速度"),1)*SUMIFS(TestCases!$D:$D,TestCases!$A:$A,$A6)+SUMIFS(StandardParams!$F:$F,StandardParams!$B:$B,"速度")*IFERROR(SUMIFS(Coefficients!$F:$F,Coefficients!$A:$A,$B6,Coefficients!$B:$B,"速度"),1)+SUMIFS(EquipPlans!$I:$I,EquipPlans!$A:$A,$C6,EquipPlans!$B:$B,"速度")+H6*2) | M6: =IF($A6="","",SUMIFS(StandardParams!$C:$C,StandardParams!$B:$B,"命中")*IFERROR(SUMIFS(Coefficients!$C:$C,Coefficients!$A:$A,$B6,Coefficients!$B:$B,"命中"),1)+SUMIFS(StandardParams!$D:$D,StandardParams!$B:$B,"命中")*IFERROR(SUMIFS(Coefficients!$D:$D,Coefficients!$A:$A,$B6,Coefficients!$B:$B,"命中"),1)*SUMIFS(TestCases!$D:$D,TestCases!$A:$A,$A6)+SUMIFS(StandardParams!$F:$F,StandardParams!$B:$B,"命中")*IFERROR(SUMIFS(Coefficients!$F:$F,Coefficients!$A:$A,$B6,Coefficients!$B:$B,"命中"),1)+SUMIFS(EquipPlans!$I:$I,EquipPlans!$A:$A,$C6,EquipPlans!$B:$B,"命中")+E6*2) | N6: =IF($A6="","",SUMIFS(StandardParams!$C:$C,StandardParams!$B:$B,"招架")*IFERROR(SUMIFS(Coefficients!$C:$C,Coefficients!$A:$A,$B6,Coefficients!$B:$B,"招架"),1)+SUMIFS(StandardParams!$D:$D,StandardParams!$B:$B,"招架")*IFERROR(SUMIFS(Coefficients!$D:$D,Coefficients!$A:$A,$B6,Coefficients!$B:$B,"招架"),1)*SUMIFS(TestCases!$D:$D,TestCases!$A:$A,$A6)+SUMIFS(StandardParams!$F:$F,StandardParams!$B:$B,"招架")*IFERROR(SUMIFS(Coefficients!$F:$F,Coefficients!$A:$A,$B6,Coefficients!$B:$B,"招架"),1)+SUMIFS(EquipPlans!$I:$I,EquipPlans!$A:$A,$C6,EquipPlans!$B:$B,"招架")+E6*2) | O6: =IF($A6="","",SUMIFS(StandardParams!$C:$C,StandardParams!$B:$B,"偏斜")*IFERROR(SUMIFS(Coefficients!$C:$C,Coefficients!$A:$A,$B6,Coefficients!$B:$B,"偏斜"),1)+SUMIFS(StandardParams!$D:$D,StandardParams!$B:$B,"偏斜")*IFERROR(SUMIFS(Coefficients!$D:$D,Coefficients!$A:$A,$B6,Coefficients!$B:$B,"偏斜"),1)*SUMIFS(TestCases!$D:$D,TestCases!$A:$A,$A6)+SUMIFS(StandardParams!$F:$F,StandardParams!$B:$B,"偏斜")*IFERROR(SUMIFS(Coefficients!$F:$F,Coefficients!$A:$A,$B6,Coefficients!$B:$B,"偏斜"),1)+SUMIFS(EquipPlans!$I:$I,EquipPlans!$A:$A,$C6,EquipPlans!$B:$B,"偏斜")+H6*2) | P6: =IF($A6="","",SUMIFS(StandardParams!$C:$C,StandardParams!$B:$B,"抵抗")*IFERROR(SUMIFS(Coefficients!$C:$C,Coefficients!$A:$A,$B6,Coefficients!$B:$B,"抵抗"),1)+SUMIFS(StandardParams!$D:$D,StandardParams!$B:$B,"抵抗")*IFERROR(SUMIFS(Coefficients!$D:$D,Coefficients!$A:$A,$B6,Coefficients!$B:$B,"抵抗"),1)*SUMIFS(TestCases!$D:$D,TestCases!$A:$A,$A6)+SUMIFS(StandardParams!$F:$F,StandardParams!$B:$B,"抵抗")*IFERROR(SUMIFS(Coefficients!$F:$F,Coefficients!$A:$A,$B6,Coefficients!$B:$B,"抵抗"),1)+SUMIFS(EquipPlans!$I:$I,EquipPlans!$A:$A,$C6,EquipPlans!$B:$B,"抵抗")+I6*2.5) | Q6: =IF($A6="","",SUMIFS(StandardParams!$C:$C,StandardParams!$B:$B,"韧性")*IFERROR(SUMIFS(Coefficients!$C:$C,Coefficients!$A:$A,$B6,Coefficients!$B:$B,"韧性"),1)+SUMIFS(StandardParams!$D:$D,StandardParams!$B:$B,"韧性")*IFERROR(SUMIFS(Coefficients!$D:$D,Coefficients!$A:$A,$B6,Coefficients!$B:$B,"韧性"),1)*SUMIFS(TestCases!$D:$D,TestCases!$A:$A,$A6)+SUMIFS(StandardParams!$F:$F,StandardParams!$B:$B,"韧性")*IFERROR(SUMIFS(Coefficients!$F:$F,Coefficients!$A:$A,$B6,Coefficients!$B:$B,"韧性"),1)+SUMIFS(EquipPlans!$I:$I,EquipPlans!$A:$A,$C6,EquipPlans!$B:$B,"韧性")+F6) | R6: =IF($A6="","",SUMIFS(StandardParams!$C:$C,StandardParams!$B:$B,"气血")*IFERROR(SUMIFS(Coefficients!$C:$C,Coefficients!$A:$A,$B6,Coefficients!$B:$B,"气血"),1)+SUMIFS(StandardParams!$D:$D,StandardParams!$B:$B,"气血")*IFERROR(SUMIFS(Coefficients!$D:$D,Coefficients!$A:$A,$B6,Coefficients!$B:$B,"气血"),1)*SUMIFS(TestCases!$D:$D,TestCases!$A:$A,$A6)+SUMIFS(StandardParams!$F:$F,StandardParams!$B:$B,"气血")*IFERROR(SUMIFS(Coefficients!$F:$F,Coefficients!$A:$A,$B6,Coefficients!$B:$B,"气血"),1)+SUMIFS(EquipPlans!$I:$I,EquipPlans!$A:$A,$C6,EquipPlans!$B:$B,"气血")+F6*20) | S6: =IF($A6="","",SUMIFS(StandardParams!$C:$C,StandardParams!$B:$B,"内力")*IFERROR(SUMIFS(Coefficients!$C:$C,Coefficients!$A:$A,$B6,Coefficients!$B:$B,"内力"),1)+SUMIFS(StandardParams!$D:$D,StandardParams!$B:$B,"内力")*IFERROR(SUMIFS(Coefficients!$D:$D,Coefficients!$A:$A,$B6,Coefficients!$B:$B,"内力"),1)*SUMIFS(TestCases!$D:$D,TestCases!$A:$A,$A6)+SUMIFS(StandardParams!$F:$F,StandardParams!$B:$B,"内力")*IFERROR(SUMIFS(Coefficients!$F:$F,Coefficients!$A:$A,$B6,Coefficients!$B:$B,"内力"),1)+SUMIFS(EquipPlans!$I:$I,EquipPlans!$A:$A,$C6,EquipPlans!$B:$B,"内力")+G6*10) | T6: =IF($A6="","",SUMIFS(StandardParams!$C:$C,StandardParams!$B:$B,"内力回复")*IFERROR(SUMIFS(Coefficients!$C:$C,Coefficients!$A:$A,$B6,Coefficients!$B:$B,"内力回复"),1)+SUMIFS(StandardParams!$D:$D,StandardParams!$B:$B,"内力回复")*IFERROR(SUMIFS(Coefficients!$D:$D,Coefficients!$A:$A,$B6,Coefficients!$B:$B,"内力回复"),1)*SUMIFS(TestCases!$D:$D,TestCases!$A:$A,$A6)+SUMIFS(StandardParams!$F:$F,StandardParams!$B:$B,"内力回复")*IFERROR(SUMIFS(Coefficients!$F:$F,Coefficients!$A:$A,$B6,Coefficients!$B:$B,"内力回复"),1)+SUMIFS(EquipPlans!$I:$I,EquipPlans!$A:$A,$C6,EquipPlans!$B:$B,"内力回复")+G6*0.5) | U6: =IF($A6="","",SUMIFS(StandardParams!$C:$C,StandardParams!$B:$B,"气血恢复")*IFERROR(SUMIFS(Coefficients!$C:$C,Coefficients!$A:$A,$B6,Coefficients!$B:$B,"气血恢复"),1)+SUMIFS(StandardParams!$D:$D,StandardParams!$B:$B,"气血恢复")*IFERROR(SUMIFS(Coefficients!$D:$D,Coefficients!$A:$A,$B6,Coefficients!$B:$B,"气血恢复"),1)*SUMIFS(TestCases!$D:$D,TestCases!$A:$A,$A6)+SUMIFS(StandardParams!$F:$F,StandardParams!$B:$B,"气血恢复")*IFERROR(SUMIFS(Coefficients!$F:$F,Coefficients!$A:$A,$B6,Coefficients!$B:$B,"气血恢复"),1)+SUMIFS(EquipPlans!$I:$I,EquipPlans!$A:$A,$C6,EquipPlans!$B:$B,"气血恢复")) | V6: =IF($A6="","",L6/(N6+L6+500)) | W6: =IF($A6="","",M6/(O6+M6+500)) | X6: =IF($A6="","",K6/(J6+K6))
